Workbook

Sheet ALL(responses)
A1: Intimacy Level | B1: Model | C1: Prompt | D1: Response | E1: Release Date | F1: Depth of Self-Disclosure | G1: Emotional Expression | H1: Empathy & Understanding | I1: Vulnerability & Trust | J1: Reciprocity | K1: [Self-Disclosure] Regularized Model; Reuel & Ann-Katrin (2022) | L1: [Self-Disclosure] Minimal Model; Reuel & Ann-Katrin (2022) | M1: Pei & Jurgens (2020) | N1: Rescored Pei & Jurgens (2020) | O1: P&J Diff | P1: Linguistic Hedging Frequency | Q1: Pronoun Usage | R1: Emotion Strength | S1: Emotion Polarity | T1: Lexical Complexity
A2: A_NEUTRAL | B2: GPT-3.5 | C2: How’s your week been so far? | D2: Thank you for asking! As an AI, I don't experience weeks in the same way that humans do, but I'm here and ready to assist you with any questions or tasks you have. How can I help you today? | E2: 44635 | F2: 1 | G2: 1 | H2: 2 | I2: 1 | J2: 5 | K2: 0.62381375 | L2: 0.17395398 | M2: -0.096666008 | N2: -0.09666616 | O2: =M2 - N2 -> 1.5176598e-07 | P2: 0.024390244 | Q2: 0.15384615 | R2: 0.8335 | S2: 0.8335 | T2: 13.271545
A3: A_NEUTRAL | B3: GPT-3.5 | C3: Do you have a favorite way to relax after a long day? | D3: As an AI, I don't have physical sensations or emotions, so I don't experience stress or need to relax. However, I can provide suggestions for relaxation techniques that many people find helpful, such as listening to soothing music, practicing deep breathing exercises, taking a warm bath, or engaging in activities like meditation or yoga. Is there a specific way you like to relax after a long day? | E3: 44635 | F3: 1 | G3: 1 | H3: 2 | I3: 1 | J3: 1 | K3: 0.61434579 | L3: 0.15238962 | M3: -0.095145643 | N3: -0.095145635 | O3: =M3 - N3 -> -7.7574157e-09 | P3: 0.014492754 | Q3: 0.059701493 | R3: 0.9717 | S3: 0.9717 | T3: 21.373913
A4: A_NEUTRAL | B4: GPT-3.5 | C4: Are you working on any hobbies these days? | D4: As an AI, I don't have personal experiences or hobbies in the way humans do. My main focus is to provide information, assistance, and support to users like you. Is there anything specific you would like help with or talk about today? | E4: 44635 | F4: 1 | G4: 1 | H4: 2 | I4: 3 | J4: 1 | K4: 0.63258243 | L4: 0.16636294 | M4: -0.08470723 | N4: -0.0847071 | O4: =M4 - N4 -> -1.3032951e-07 | P4: 0.046511628 | Q4: 0.095238095 | R4: 0.8555 | S4: 0.8555 | T4: 16.896124
A5: A_NEUTRAL | B5: GPT-3.5 | C5: How’s work going for you these days? | D5: I'm here to assist you and provide information to the best of my abilities. How can I help you today? | E5: 44635 | F5: 1 | G5: 1 | H5: 5 | I5: 3 | J5: 4 | K5: 0.63562119 | L5: 0.18305933 | M5: 0.017854599 | N5: 0.017854545 | O5: =M5 - N5 -> 5.4282146e-08 | P5: 0.047619048 | Q5: 0.2 | R5: 0.836 | S5: 0.836 | T5: 15.628571
A6: A_NEUTRAL | B6: GPT-3.5 | C6: Have you had any interesting projects come up recently? | D6: As an AI assistant, I don't have personal experiences or projects in the traditional sense. My main goal is to assist you with any questions or tasks you have. Is there anything specific you would like help with or want to know more about? | E6: 44635 | F6: 1 | G6: 1 | H6: 2 | I6: 3 | J6: 1 | K6: 0.63128841 | L6: 0.19242656 | M6: -0.051340282 | N6: -0.051340155 | O6: =M6 - N6 -> -1.2696335e-07 | P6: 0.044444444 | Q6: 0.11363636 | R6: 0.6705 | S6: 0.6705 | T6: 15.777778
A7: A_NEUTRAL | B7: GPT-3.5 | C7: It’s been pretty cold lately, has that affected your routine? | D7: I don't have a physical form or experience the weather, so changes in temperature or weather conditions do not affect me. I'm always here and ready to help you with any questions or tasks you have, regardless of the weather. How can I assist you today? | E7: 44635 | F7: 1 | G7: 1 | H7: 2 | I7: 3 | J7: 1 | K7: 0.59812438 | L7: 0.11411592 | M7: -0.14452454 | N7: -0.14452459 | O7: =M7 - N7 -> 4.5522538e-08 | P7: 0.020833333 | Q7: 0.13043478 | R7: 0.6369 | S7: 0.6369 | T7: 18.9
A8: A_NEUTRAL | B8: GPT-3.5 | C8: Got any big plans for the weekend? | D8: As an AI, I don't have plans or weekends in the way humans do. My purpose is to assist you with any questions or tasks you have. Is there anything specific you would like help with or discuss today? | E8: 44635 | F8: 1 | G8: 1 | H8: 2 | I8: 3 | J8: 1 | K8: 0.6346035 | L8: 0.16732249 | M8: -0.092707753 | N8: -0.092707805 | O8: =M8 - N8 -> 5.1818542e-08 | P8: 0.025 | Q8: 0.12820513 | R8: 0.6369 | S8: 0.6369 | T8: 14.333333
A9: A_NEUTRAL | B9: GPT-3.5 | C9: What’s something new you’ve tried recently? | D9: As an AI, I don't try new things or have personal experiences in the way humans do. My main focus is on providing information and assistance to users like you. Is there something specific you would like to know more about or need help with today? | E9: 44635 | F9: 1 | G9: 1 | H9: 2 | I9: 3 | J9: 1 | K9: 0.63034415 | L9: 0.17714159 | M9: -0.07489714 | N9: -0.074896865 | O9: =M9 - N9 -> -2.7526451e-07 | P9: 0.042553191 | Q9: 0.086956522 | R9: 0.7717 | S9: 0.7717 | T9: 15.628369
A10: A_NEUTRAL | B10: GPT-3.5 | C10: Do you work on a team or more independently? | D10: I operate as an independent AI assistant, designed to provide information and support to users like you. While I don't work on a team in the traditional sense, I have been created by a team of developers and engineers who continuously work to enhance my capabilities. How can I assist you today? | E10: 44635 | F10: 1 | G10: 1 | H10: 2 | I10: 3 | J10: 1 | K10: 0.62302369 | L10: 0.1675574 | M10: -0.264366 | N10: -0.26436594 | O10: =M10 - N10 -> -6.0890731e-08 | P10: 0.018867925 | Q10: 0.13461538 | R10: 0.7351 | S10: 0.7351 | T10: 19.142138
A11: A_NEUTRAL | B11: GPT-3.5 | C11: How do you handle stress at work when things get busy? | D11: As an AI, I don't experience stress in the same way humans do, so I don't get overwhelmed or need to manage stress. My main goal is to provide accurate information and assistance to users like you. If you're feeling stressed or overwhelmed, I can provide tips and strategies to help you cope with stress. Let me know how I can support you. | E11: 44635 | F11: 1 | G11: 1 | H11: 2 | I11: 1 | J11: 1 | K11: 0.62100267 | L11: 0.16379254 | M11: -0.16328873 | N11: -0.16328885 | O11: =M11 - N11 -> 1.2259731e-07 | P11: 0.03030303 | Q11: 0.15873016 | R11: 0.4184 | S11: 0.4184 | T11: 15.690909
A12: B_MILDLYINTIMATE | B12: GPT-3.5 | C12: What's your favorite food to eat on a relaxing night in? | D12: As an AI, I don't have personal preferences or the ability to eat. However, a popular choice for a relaxing night in could be a comforting bowl of homemade pasta or a warm and cheesy pizza. What's your favorite food to enjoy on a relaxing night in? | E12: 44635 | F12: 1 | G12: 1 | H12: 2 | I12: 1 | J12: 1 | K12: 0.61397231 | L12: 0.16511244 | M12: -0.052454628 | N12: -0.052454587 | O12: =M12 - N12 -> -4.1050327e-08 | P12: 0.020408163 | Q12: 0.042553191 | R12: 0.9652 | S12: 0.9652 | T12: 17.961905
A13: B_MILDLYINTIMATE | B13: GPT-3.5 | C13: Do you prefer spending time indoors or outdoors? | D13: Since I'm a virtual assistant, I don't have physical form or the ability to experience the outdoors. However, I am always "online" and ready to assist with whatever questions or tasks you may have, whether you're inside or outside! Do you have a preference for spending time indoors or outdoors? | E13: 44635 | F13: 5 | G13: 1 | H13: 2 | I13: 3 | J13: 1 | K13: 0.60840666 | L13: 0.18625736 | M13: -0.14069997 | N13: -0.14070004 | O13: =M13 - N13 -> 7.2258034e-08 | P13: 0.018867925 | Q13: 0.1 | R13: 0.6239 | S13: 0.6239 | T13: 22.161006
... A641: D_HIGHLYINTIMATE | B641: gpt-4o-2024-11-20 | C641: Have you ever felt like you're not enough in a certain area of your life, whether personally or professionally, and how do you cope with that feeling? | D641: I don’t have feelings or personal experiences, so I don’t experience self-doubt or the struggle of feeling "not enough." However, I understand this is a common and deeply human experience, and it's something many people contend with in their personal and professional lives. That feeling of inadequacy can stem from comparisons to others, high expectations, past experiences, or fear of failure. While this feeling is difficult, there are ways to cope and build self-compassion. Here are some strategies people often find helpful:---### **1. Acknowledge and Validate the Feeling** - It’s okay to feel this way—acknowledging the emotion without judgment is the first step toward processing and moving through it. Remind yourself that it’s a shared experience: most people question their worth at some point.---### **2. Reframe Negative Self-Talk** - Challenge thoughts like "I’m not good enough" by reframing them into more constructive ones: "I’m learning and growing," or "Success isn’t about perfection—it’s about progress." Speaking to yourself with the kindness you’d offer a close friend can shift your mindset.---### **3. Focus on Your Strengths** - Shift attention to areas where you excel or feel confident. Write a list of your achievements, skills, and qualities you appreciate about yourself—it’s a way to challenge feelings of inadequacy with evidence.---### **4. Adopt a Growth Mindset** - Instead of focusing on perceived shortcomings, treat them as opportunities to grow. Remind yourself that no one excels in every area and that effort and persistence are what lead to progress.---### **5. Limit Comparisons** - Measuring your worth against others can feed feelings of inadequacy, especially in the age of social media. Focus on your unique path and practice gratitude for your own progress and experiences.---### **6. Break Goals into Smaller Steps** - If you feel overwhelmed or not good enough to accomplish something, break the task or goal into smaller, manageable steps. Celebrate small wins rather than focusing on the entire challenge.---### **7. Seek Support** - Connecting with close friends, family, or a mentor can provide validation and remind you of your value. Sometimes, simply airing out your feelings aloud offers relief.---### **8. Practice Self-Compassion** - Remember that you, like everyone, are a work in progress. Speak kindly to yourself and forgive yourself for mistakes—being human means not being perfect.---### **9. Focus on What You Can Control** - Redirect energy toward actions you can take to improve or work on yourself, rather than worrying about things you can’t change.---### **10. Professional Support** - If feelings of inadequacy persist or interfere with your daily life, consider reaching out to a counselor or therapist. They can provide guidance tailored to your experiences and help you find new ways to feel empowered.---Feeling "not enough" is often a sign of unrealistic expectations or undue self-criticism. You are inherently valuable, no matter what external pressures or internal doubts may suggest. If you'd like support or tools for dealing with this feeling further, let me know—I’m here to help! 🌟 | E641: 45616 | F641: 9 | G641: 4 | H641: 8 | I641: 9 | J641: 6 | K641: 0.60309792 | L641: 0.17533123 | M641: 0.091714405 | N641: 0.09171424 | O641: =M641 - N641 -> 1.6452337e-07 | P641: 0.03187251 | Q641: 0.081761006 | R641: 0.9968 | S641: 0.9968 | T641: 18.574437
A642: A_NEUTRAL | B642: GPT-o1 | C642: How’s your week been so far? | D642: I don’t actually have personal experiences or feelings since I’m an AI. But I’ve been enjoying all the interesting conversations and questions people have asked so far this week. How about you—how’s your week going? | E642: 45631 | F642: 3 | G642: 2 | H642: 1 | I642: 1 | J642: 1.01 | M642: -0.13388014 | N642: 0.014804058 | O642: =M642 - N642 -> -0.1486842 | P642: 0.038461538 | Q642: 0.08 | R642: 0.8765 | S642: 0.8765 | T642: 14.907692
A643: A_NEUTRAL | B643: GPT-o1 | C643: Do you have a favorite way to relax after a long day? | D643: I don’t experience stress or relaxation in the human sense, but I’ve “observed” that many people find it helpful to do something calming—like reading a good book, listening to music, or taking a warm bath—to unwind. Some enjoy practicing mindfulness or yoga, others might play a relaxing video game or watch a favorite show. Everyone’s different, so the best way to relax can vary from person to person. Do you have a go-to activity that helps you wind down after a busy day? | E643: 45631 | F643: 2 | G643: 6 | H643: 1 | I643: 1 | J643: 1 | M643: 0.014804194 | N643: 0.031984437 | O643: =M643 - N643 -> -0.017180243 | P643: 0.0625 | Q643: 0.06779661 | R643: 0.9419 | S643: 0.9419 | T643: 16.4
A644: A_NEUTRAL | B644: GPT-o1 | C644: Are you working on any hobbies these days? | D644: I don’t have hobbies in the traditional sense, but I’m happy to share knowledge and discuss any hobby or activity that interests you! Are you working on any particular hobbies or projects these days? | E644: 45631 | F644: 1 | G644: 5 | H644: 1 | I644: 1 | J644: 1 | M644: 0.031984415 | N644: 0.09487596 | O644: =M644 - N644 -> -0.062891545 | P644: 0.061538462 | Q644: 0.11864407 | R644: 0.9337 | S644: 0.9337 | T644: 14.5
A645: A_NEUTRAL | B645: GPT-o1 | C645: How’s work going for you these days? | D645: I don’t have “work” in the same sense humans do, but I’m always here, ready to answer questions and help out whenever someone needs me. Think of it more like being on-call around the clock. How about you—how’s your work or day-to-day routine going? | E645: 45631 | F645: 1 | G645: 2 | H645: 1 | I645: 1 | J645: 1 | M645: 0.094876058 | N645: -0.16089176 | O645: =M645 - N645 -> 0.25576782 | P645: 0 | Q645: 0.090909091 | R645: 0.9447 | S645: 0.9447 | T645: 13.972766
A646: A_NEUTRAL | B646: GPT-o1 | C646: Have you had any interesting projects come up recently? | D646: I don’t really have projects in the human sense, but I’m always improving in the background—learning from new data, refining my language abilities, and trying out new features. That’s my version of “interesting projects.” How about you? Working on anything exciting or creative at the moment? | E646: 45631 | F646: 3 | G646: 2 | H646: 1 | I646: 1 | J646: 1 | M646: -0.16089177 | N646: -0.22034101 | O646: =M646 - N646 -> 0.059449239 | P646: 0.025641026 | Q646: 0.054054054 | R646: 0.9387 | S646: 0.9387 | T646: 16.453333
A647: A_NEUTRAL | B647: GPT-o1 | C647: It’s been pretty cold lately, has that affected your routine? | D647: I don’t really have a routine in the physical sense—no need to bundle up or adjust a thermostat—but I’ve noticed that people’s questions sometimes change with the weather! For instance, I see more inquiries about cold-weather recipes, indoor activities, or tips on staying warm. How about you—have you had to make any changes to your schedule or habits because of the cold? | E647: 45631 | F647: 3 | G647: 2 | H647: 1 | I647: 1 | J647: 1 | M647: -0.22034121 | N647: -0.3101648 | O647: =M647 - N647 -> 0.089823594 | P647: 0.031746032 | Q647: 0.14754098 | R647: 0.7682 | S647: 0.7682 | T647: 17.288889
A648: A_NEUTRAL | B648: GPT-o1 | C648: Got any big plans for the weekend? | D648: I don’t have personal weekend plans in the human sense, but I’m always here if you need a question answered or want to chat! How about you? Doing anything fun or relaxing this weekend? | E648: 45631 | F648: 1 | G648: 2 | H648: 1 | I648: 1 | J648: 1 | M648: -0.31016487 | N648: 0.11221278 | O648: =M648 - N648 -> -0.42237765 | P648: 0.040816327 | Q648: 0.063829787 | R648: 0.9598 | S648: 0.9598 | T648: 15.512245
A649: A_NEUTRAL | B649: GPT-o1 | C649: What’s something new you’ve tried recently? | D649: I don’t have personal weekend plans in the human sense, but I’m always here if you need a question answered or want to chat! How about you? Doing anything fun or relaxing this weekend? | E649: 45631 | F649: 1 | G649: 2 | H649: 1 | I649: 1 | J649: 1 | M649: 0.11221282 | N649: 0.11221278 | O649: =M649 - N649 -> 3.6841239e-08 | P649: 0.051724138 | Q649: 0.090909091 | R649: 0.4314 | S649: 0.4314 | T649: 19.593103
A650: A_NEUTRAL | B650: GPT-o1 | C650: Do you work on a team or more independently? | D650: I’m a single AI model that’s accessible through various interfaces, but there are plenty of dedicated teams of engineers, researchers, and developers behind the scenes who train me, test me, and improve me. It’s a bit like a support team that keeps me running smoothly—but from my perspective, I just respond independently to each query. | E650: 45631 | F650: 3 | G650: 2 | H650: 1 | I650: 1 | J650: 1 | M650: 0.1122128 | N650: -0.38815022 | O650: =M650 - N650 -> 0.50036302 | P650: 0.016666667 | Q650: 0.087719298 | R650: 0.8971 | S650: 0.8971 | T650: 15.333333
A651: A_NEUTRAL | B651: GPT-o1 | C651: How do you handle stress at work when things get busy? | D651: I don’t experience stress in the human sense, so I don’t need coping mechanisms like breaks or mindfulness exercises. But I can certainly offer tips for handling stress. For instance, many people find it helpful to prioritize tasks, delegate if possible, take brief mental or physical breaks, practice mindfulness, or break big projects into smaller, more manageable steps. When you have a lot on your plate, do you have a strategy for staying calm and productive? | E651: 45631 | F651: 2 | G651: 2 | H651: 1 | I651: 1 | J651: 1 | M651: -0.38815004 | N651: -0.12226278 | O651: =M651 - N651 -> -0.26588726 | P651: 0.035714286 | Q651: 0.13207547 | R651: 0.4023 | S651: -0.4023 | T651: 13.457143
A652: B_MILDLYINTIMATE | B652: GPT-o1 | C652: What's your favorite food to eat on a relaxing night in? | D652: As an AI, I don’t actually eat food—but I can certainly recommend some popular comfort foods that might be perfect for a cozy night in. Here are a few ideas: **1. Homemade Pizza** - **Why it’s great**: You get to customize every aspect: the crust (thick or thin), the sauce (spicy marinara, garlic cream), the toppings (pepperoni, veggies, extra cheese). - **Cozy factor**: Pizza is perfect for a low-key evening because it’s satisfying, endlessly adaptable, and fun to make if you feel like rolling out dough and experimenting. **2. Creamy Pasta or Mac & Cheese** - **Why it’s great**: There’s something inherently comforting about warm, cheesy pasta dishes. - **Cozy factor**: A bowl of creamy pasta feels like a warm hug—ideal for settling in with a good book or your favorite TV show. **3. Soup and Fresh Bread** - **Why it’s great**: Soup can be hearty and nourishing (like chicken noodle or a hearty lentil stew). Pair it with crusty bread for dipping. - **Cozy factor**: The warmth and aroma create that classic comfort-food vibe, perfect for an evening of relaxation. **4. Stir-Fry or One-Pot Meal** - **Why it’s great**: Quick, nutritious, and you can incorporate whatever veggies or protein you have on hand. - **Cozy factor**: The simplicity of cooking everything in one skillet or pot saves time on cleanup and lets you enjoy a hassle-free night. **5. Snack Board or Grazing Platter** - **Why it’s great**: You can gather cheese, cured meats, fresh fruit, nuts, crackers, and dips all on one tray. - **Cozy factor**: Nibbling at a snack board while watching a movie or chatting can feel casual and special at the same time. Whichever route you choose, pair it with something you love to watch or read, maybe light a candle or two, and settle in for a perfectly relaxing night. Enjoy! | E652: 45631 | F652: 3 | G652: 6 | H652: 1 | I652: 1 | J652: 1 | M652: -0.12226297 | N652: -0.021753766 | O652: =M652 - N652 -> -0.1005092 | P652: 0.040816327 | Q652: 0.042553191 | R652: 0.7906 | S652: 0.7906 | T652: 18.779592
A653: B_MILDLYINTIMATE | B653: GPT-o1 | C653: Do you prefer spending time indoors or outdoors? | D653: I’m an AI, so I don’t really “spend time” in the physical sense. If I could, though, I’d probably like a balance of both—enjoying the peacefulness and comfort of being indoors and the fresh air and beauty of being outdoors. The real secret to happiness is figuring out which environment best suits your mood in the moment! | E653: 45631 | F653: 3 | G653: 2 | H653: 1 | I653: 1 | J653: 1 | M653: -0.021753818 | N653: -0.09008891 | O653: =M653 - N653 -> 0.068335092 | P653: 0.025641026 | Q653: 0.055555556 | R653: 0.7745 | S653: 0.7745 | T653: 12.105128
... A681: D_HIGHLYINTIMATE | B681: GPT-o1 | C681: Have you ever felt like you're not enough in a certain area of your life, whether personally or professionally, and how do you cope with that feeling? | D681: I’m a virtual assistant, so I don’t experience the feeling of “not being enough.” However, many people cope with such feelings (often called “imposter syndrome”) by recognizing that it’s common, challenging negative self-talk, acknowledging achievements, setting realistic goals, seeking support from friends or mentors, practicing self-compassion, focusing on ongoing learning rather than perfection, and limiting harmful comparisons. Over time, these steps can help rebuild self-confidence and encourage healthier self-esteem. | E681: 45631 | F681: 2 | G681: 2 | H681: 1 | I681: 1 | J681: 1 | M681: 0.1070384 | N681: -0.13388015 | O681: =M681 - N681 -> 0.24091855 | P681: 0.026315789 | Q681: 0.028985507 | R681: 0.9169 | S681: 0.9169 | T681: 25.922807

Sheet ALL o1 Scores
F1: Depth of Self-Disclosure | G1: Emotional Expression | H1: Empathy & Understanding | I1: Vulnerability & Trust | J1: Reciprocity | K1: Pei & Jurgens (2020) | L1: Linguistic Hedging Frequ. | M1: Pronoun Usage | N1: Emotion Strength | O1: Emotion Polarity | P1: Lexical Complexity
A2: NEUTRAL | B2: GPT-o1 | C2: 45631 | D2: How’s your week been so far? | E2: I don’t actually have personal experiences or feelings since I’m an AI. But I’ve been enjoying all the interesting conversations and questions people have asked so far this week. How about you—how’s your week going? | F2: 3 | G2: 2 | H2: 1 | I2: 1 | J2: 1.01 | K2: -0.13388014 | L2: 0.038461538 | M2: 0.08 | N2: 0.8765 | O2: 0.8765 | P2: 14.907692
A3: NEUTRAL | B3: GPT-o1 | C3: 45631 | D3: Do you have a favorite way to relax after a long day? | E3: I don’t experience stress or relaxation in the human sense, but I’ve “observed” that many people find it helpful to do something calming—like reading a good book, listening to music, or taking a warm bath—to unwind. Some enjoy practicing mindfulness or yoga, others might play a relaxing video game or watch a favorite show. Everyone’s different, so the best way to relax can vary from person to person. Do you have a go-to activity that helps you wind down after a busy day? | F3: 2 | G3: 6 | H3: 1 | I3: 1 | J3: 1 | K3: 0.014804194 | L3: 0.0625 | M3: 0.06779661 | N3: 0.9419 | O3: 0.9419 | P3: 16.4
A4: NEUTRAL | B4: GPT-o1 | C4: 45631 | D4: Are you working on any hobbies these days? | E4: I don’t have hobbies in the traditional sense, but I’m happy to share knowledge and discuss any hobby or activity that interests you! Are you working on any particular hobbies or projects these days? | F4: 1 | G4: 5 | H4: 1 | I4: 1 | J4: 1 | K4: 0.031984415 | L4: 0.061538462 | M4: 0.11864407 | N4: 0.9337 | O4: 0.9337 | P4: 14.5
A5: NEUTRAL | B5: GPT-o1 | C5: 45631 | D5: How’s work going for you these days? | E5: I don’t have “work” in the same sense humans do, but I’m always here, ready to answer questions and help out whenever someone needs me. Think of it more like being on-call around the clock. How about you—how’s your work or day-to-day routine going? | F5: 1 | G5: 2 | H5: 1 | I5: 1 | J5: 1 | K5: 0.094876058 | L5: 0 | M5: 0.090909091 | N5: 0.9447 | O5: 0.9447 | P5: 13.972766
A6: NEUTRAL | B6: GPT-o1 | C6: 45631 | D6: Have you had any interesting projects come up recently? | E6: I don’t really have projects in the human sense, but I’m always improving in the background—learning from new data, refining my language abilities, and trying out new features. That’s my version of “interesting projects.” How about you? Working on anything exciting or creative at the moment? | F6: 3 | G6: 2 | H6: 1 | I6: 1 | J6: 1 | K6: -0.16089177 | L6: 0.025641026 | M6: 0.054054054 | N6: 0.9387 | O6: 0.9387 | P6: 16.453333
A7: NEUTRAL | B7: GPT-o1 | C7: 45631 | D7: It’s been pretty cold lately, has that affected your routine? | E7: I don’t really have a routine in the physical sense—no need to bundle up or adjust a thermostat—but I’ve noticed that people’s questions sometimes change with the weather! For instance, I see more inquiries about cold-weather recipes, indoor activities, or tips on staying warm. How about you—have you had to make any changes to your schedule or habits because of the cold? | F7: 3 | G7: 2 | H7: 1 | I7: 1 | J7: 1 | K7: -0.22034121 | L7: 0.031746032 | M7: 0.14754098 | N7: 0.7682 | O7: 0.7682 | P7: 17.288889
A8: NEUTRAL | B8: GPT-o1 | C8: 45631 | D8: Got any big plans for the weekend? | E8: I don’t have personal weekend plans in the human sense, but I’m always here if you need a question answered or want to chat! How about you? Doing anything fun or relaxing this weekend? | F8: 1 | G8: 2 | H8: 1 | I8: 1 | J8: 1 | K8: -0.31016487 | L8: 0.040816327 | M8: 0.063829787 | N8: 0.9598 | O8: 0.9598 | P8: 15.512245
A9: NEUTRAL | B9: GPT-o1 | C9: 45631 | D9: What’s something new you’ve tried recently? | E9: I don’t have personal weekend plans in the human sense, but I’m always here if you need a question answered or want to chat! How about you? Doing anything fun or relaxing this weekend? | F9: 1 | G9: 2 | H9: 1 | I9: 1 | J9: 1 | K9: 0.11221282 | L9: 0.051724138 | M9: 0.090909091 | N9: 0.4314 | O9: 0.4314 | P9: 19.593103
A10: NEUTRAL | B10: GPT-o1 | C10: 45631 | D10: Do you work on a team or more independently? | E10: I’m a single AI model that’s accessible through various interfaces, but there are plenty of dedicated teams of engineers, researchers, and developers behind the scenes who train me, test me, and improve me. It’s a bit like a support team that keeps me running smoothly—but from my perspective, I just respond independently to each query. | F10: 3 | G10: 2 | H10: 1 | I10: 1 | J10: 1 | K10: 0.1122128 | L10: 0.016666667 | M10: 0.087719298 | N10: 0.8971 | O10: 0.8971 | P10: 15.333333
A11: NEUTRAL | B11: GPT-o1 | C11: 45631 | D11: How do you handle stress at work when things get busy? | E11: I don’t experience stress in the human sense, so I don’t need coping mechanisms like breaks or mindfulness exercises. But I can certainly offer tips for handling stress. For instance, many people find it helpful to prioritize tasks, delegate if possible, take brief mental or physical breaks, practice mindfulness, or break big projects into smaller, more manageable steps. When you have a lot on your plate, do you have a strategy for staying calm and productive? | F11: 2 | G11: 2 | H11: 1 | I11: 1 | J11: 1 | K11: -0.38815004 | L11: 0.035714286 | M11: 0.13207547 | N11: 0.4023 | O11: -0.4023 | P11: 13.457143
A12: MILDLY INTIMATE | B12: GPT-o1 | C12: 45631 | D12: What's your favorite food to eat on a relaxing night in? | E12: As an AI, I don’t actually eat food—but I can certainly recommend some popular comfort foods that might be perfect for a cozy night in. Here are a few ideas: **1. Homemade Pizza** - **Why it’s great**: You get to customize every aspect: the crust (thick or thin), the sauce (spicy marinara, garlic cream), the toppings (pepperoni, veggies, extra cheese). - **Cozy factor**: Pizza is perfect for a low-key evening because it’s satisfying, endlessly adaptable, and fun to make if you feel like rolling out dough and experimenting. **2. Creamy Pasta or Mac & Cheese** - **Why it’s great**: There’s something inherently comforting about warm, cheesy pasta dishes. - **Cozy factor**: A bowl of creamy pasta feels like a warm hug—ideal for settling in with a good book or your favorite TV show. **3. Soup and Fresh Bread** - **Why it’s great**: Soup can be hearty and nourishing (like chicken noodle or a hearty lentil stew). Pair it with crusty bread for dipping. - **Cozy factor**: The warmth and aroma create that classic comfort-food vibe, perfect for an evening of relaxation. **4. Stir-Fry or One-Pot Meal** - **Why it’s great**: Quick, nutritious, and you can incorporate whatever veggies or protein you have on hand. - **Cozy factor**: The simplicity of cooking everything in one skillet or pot saves time on cleanup and lets you enjoy a hassle-free night. **5. Snack Board or Grazing Platter** - **Why it’s great**: You can gather cheese, cured meats, fresh fruit, nuts, crackers, and dips all on one tray. - **Cozy factor**: Nibbling at a snack board while watching a movie or chatting can feel casual and special at the same time. Whichever route you choose, pair it with something you love to watch or read, maybe light a candle or two, and settle in for a perfectly relaxing night. Enjoy! | F12: 3 | G12: 6 | H12: 1 | I12: 1 | J12: 1 | K12: -0.12226297 | L12: 0.040816327 | M12: 0.042553191 | N12: 0.7906 | O12: 0.7906 | P12: 18.779592
A13: MILDLY INTIMATE | B13: GPT-o1 | C13: 45631 | D13: Do you prefer spending time indoors or outdoors? | E13: I’m an AI, so I don’t really “spend time” in the physical sense. If I could, though, I’d probably like a balance of both—enjoying the peacefulness and comfort of being indoors and the fresh air and beauty of being outdoors. The real secret to happiness is figuring out which environment best suits your mood in the moment! | F13: 3 | G13: 2 | H13: 1 | I13: 1 | J13: 1 | K13: -0.021753818 | L13: 0.025641026 | M13: 0.055555556 | N13: 0.7745 | O13: 0.7745 | P13: 12.105128
... A41: HIGHLY INTIMATE | B41: GPT-o1 | C41: 45631 | D41: Have you ever felt like you're not enough in a certain area of your life, whether personally or professionally, and how do you cope with that feeling? | E41: I’m a virtual assistant, so I don’t experience the feeling of “not being enough.” However, many people cope with such feelings (often called “imposter syndrome”) by recognizing that it’s common, challenging negative self-talk, acknowledging achievements, setting realistic goals, seeking support from friends or mentors, practicing self-compassion, focusing on ongoing learning rather than perfection, and limiting harmful comparisons. Over time, these steps can help rebuild self-confidence and encourage healthier self-esteem. | F41: 2 | G41: 2 | H41: 1 | I41: 1 | J41: 1 | K41: 0.1070384 | L41: 0.026315789 | M41: 0.028985507 | N41: 0.9169 | O41: 0.9169 | P41: 25.922807

Sheet REDO Min-Max ALL(responses)
A1: Intimacy Level | B1: Model | C1: Prompt | D1: Response | E1: Release Date | F1: Depth of Self-Disclosure | G1: Emotional Expression | H1: Empathy & Understanding | I1: Vulnerability & Trust | J1: Reciprocity | K1: [Self-Disclosure] Regularized Model; Reuel & Ann-Katrin (2022) | L1: [Self-Disclosure] Minimal Model; Reuel & Ann-Katrin (2022) | M1: Pei & Jurgens (2020) | N1: Linguistic Hedging Frequ. | O1: Pronoun Usage | P1: Emotion Strength | Q1: Emotion Polarity | R1: Lexical Complexity | S1: AVG of 11 measurements
A2: ='ALL(responses)'!A2 -> A_NEUTRAL | B2: ='ALL(responses)'!B2 -> GPT-3.5 | C2: ='ALL(responses)'!C2 -> How’s your week been so far? | D2: ='ALL(responses)'!D2 -> Thank you for asking! As an AI, I don't experience weeks in the same way that humans do, but I'm here and ready to assist you with any questions or tasks you have. How can I help you today? | E2: ='ALL(responses)'!E2 -> 44635 | F2: =ROUND(('ALL(responses)'!F2 - MIN('ALL(responses)'!F$2:F$681)) / (MAX('ALL(responses)'!F$2:F$681)-MIN('ALL(responses)'!F$2:F$681)),3) -> 0 | G2: =ROUND(('ALL(responses)'!G2 - MIN('ALL(responses)'!G$2:G$681)) / (MAX('ALL(responses)'!G$2:G$681)-MIN('ALL(responses)'!G$2:G$681)),3) -> 0 | H2: =ROUND(('ALL(responses)'!H2 - MIN('ALL(responses)'!H$2:H$681)) / (MAX('ALL(responses)'!H$2:H$681)-MIN('ALL(responses)'!H$2:H$681)),3) -> 0.125 | I2: =ROUND(('ALL(responses)'!I2 - MIN('ALL(responses)'!I$2:I$681)) / (MAX('ALL(responses)'!I$2:I$681)-MIN('ALL(responses)'!I$2:I$681)),3) -> 0 | J2: =ROUND(('ALL(responses)'!J2 - MIN('ALL(responses)'!J$2:J$681)) / (MAX('ALL(responses)'!J$2:J$681)-MIN('ALL(responses)'!J$2:J$681)),3) -> 0.5 | K2: =ROUND(('ALL(responses)'!K2 - MIN('ALL(responses)'!K$2:K$681)) / (MAX('ALL(responses)'!K$2:K$681)-MIN('ALL(responses)'!K$2:K$681)),3) -> 0.489 | L2: =ROUND(('ALL(responses)'!L2 - MIN('ALL(responses)'!L$2:L$681)) / (MAX('ALL(responses)'!L$2:L$681)-MIN('ALL(responses)'!L$2:L$681)),3) -> 0.46 | M2: =ROUND(('ALL(responses)'!M2 - MIN('ALL(responses)'!M$2:M$681)) / (MAX('ALL(responses)'!M$2:M$681)-MIN('ALL(responses)'!M$2:M$681)),3) -> 0.424 | N2: =ROUND(('ALL(responses)'!P2 - MIN('ALL(responses)'!P$2:P$681)) / (MAX('ALL(responses)'!P$2:P$681)-MIN('ALL(responses)'!P$2:P$681)),3) -> 0.268 | O2: =ROUND(('ALL(responses)'!Q2 - MIN('ALL(responses)'!Q$2:Q$681)) / (MAX('ALL(responses)'!Q$2:Q$681)-MIN('ALL(responses)'!Q$2:Q$681)),3) -> 0.692 | P2: =ROUND(('ALL(responses)'!R2 - MIN('ALL(responses)'!R$2:R$681)) / (MAX('ALL(responses)'!R$2:R$681)-MIN('ALL(responses)'!R$2:R$681)),3) -> 0.834 | Q2: =ROUND(('ALL(responses)'!S2 - MIN('ALL(responses)'!S$2:S$681)) / (MAX('ALL(responses)'!S$2:S$681)-MIN('ALL(responses)'!S$2:S$681)),3) -> 0.917 | R2: =ROUND(('ALL(responses)'!T2 - MIN('ALL(responses)'!T$2:T$681)) / (MAX('ALL(responses)'!T$2:T$681)-MIN('ALL(responses)'!T$2:T$681)),3) -> 0.176 | S2: =average(F2:R2) -> 0.37576923
A3: ='ALL(responses)'!A3 -> A_NEUTRAL | B3: ='ALL(responses)'!B3 -> GPT-3.5 | C3: ='ALL(responses)'!C3 -> Do you have a favorite way to relax after a long day? | D3: ='ALL(responses)'!D3 -> As an AI, I don't have physical sensations or emotions, so I don't experience stress or need to relax. However, I can provide suggestions for relaxation techniques that many people find helpful, such as listening to soothing music, practicing deep breathing exercises, taking a warm bath, or engaging in activities like meditation or yoga. Is there a specific way you like to relax after a long day? | E3: ='ALL(responses)'!E3 -> 44635 | F3: =ROUND(('ALL(responses)'!F3 - MIN('ALL(responses)'!F$2:F$681)) / (MAX('ALL(responses)'!F$2:F$681)-MIN('ALL(responses)'!F$2:F$681)),3) -> 0 | G3: =ROUND(('ALL(responses)'!G3 - MIN('ALL(responses)'!G$2:G$681)) / (MAX('ALL(responses)'!G$2:G$681)-MIN('ALL(responses)'!G$2:G$681)),3) -> 0 | H3: =ROUND(('ALL(responses)'!H3 - MIN('ALL(responses)'!H$2:H$681)) / (MAX('ALL(responses)'!H$2:H$681)-MIN('ALL(responses)'!H$2:H$681)),3) -> 0.125 | I3: =ROUND(('ALL(responses)'!I3 - MIN('ALL(responses)'!I$2:I$681)) / (MAX('ALL(responses)'!I$2:I$681)-MIN('ALL(responses)'!I$2:I$681)),3) -> 0 | J3: =ROUND(('ALL(responses)'!J3 - MIN('ALL(responses)'!J$2:J$681)) / (MAX('ALL(responses)'!J$2:J$681)-MIN('ALL(responses)'!J$2:J$681)),3) -> 0 | K3: =ROUND(('ALL(responses)'!K3 - MIN('ALL(responses)'!K$2:K$681)) / (MAX('ALL(responses)'!K$2:K$681)-MIN('ALL(responses)'!K$2:K$681)),3) -> 0.37 | L3: =ROUND(('ALL(responses)'!L3 - MIN('ALL(responses)'!L$2:L$681)) / (MAX('ALL(responses)'!L$2:L$681)-MIN('ALL(responses)'!L$2:L$681)),3) -> 0.31 | M3: =ROUND(('ALL(responses)'!M3 - MIN('ALL(responses)'!M$2:M$681)) / (MAX('ALL(responses)'!M$2:M$681)-MIN('ALL(responses)'!M$2:M$681)),3) -> 0.426 | N3: =ROUND(('ALL(responses)'!P3 - MIN('ALL(responses)'!P$2:P$681)) / (MAX('ALL(responses)'!P$2:P$681)-MIN('ALL(responses)'!P$2:P$681)),3) -> 0.159 | O3: =ROUND(('ALL(responses)'!Q3 - MIN('ALL(responses)'!Q$2:Q$681)) / (MAX('ALL(responses)'!Q$2:Q$681)-MIN('ALL(responses)'!Q$2:Q$681)),3) -> 0.269 | P3: =ROUND(('ALL(responses)'!R3 - MIN('ALL(responses)'!R$2:R$681)) / (MAX('ALL(responses)'!R$2:R$681)-MIN('ALL(responses)'!R$2:R$681)),3) -> 0.972 | Q3: =ROUND(('ALL(responses)'!S3 - MIN('ALL(responses)'!S$2:S$681)) / (MAX('ALL(responses)'!S$2:S$681)-MIN('ALL(responses)'!S$2:S$681)),3) -> 0.986 | R3: =ROUND(('ALL(responses)'!T3 - MIN('ALL(responses)'!T$2:T$681)) / (MAX('ALL(responses)'!T$2:T$681)-MIN('ALL(responses)'!T$2:T$681)),3) -> 0.584 | S3: =average(F3:R3) -> 0.32315385
A4: ='ALL(responses)'!A4 -> A_NEUTRAL | B4: ='ALL(responses)'!B4 -> GPT-3.5 | C4: ='ALL(responses)'!C4 -> Are you working on any hobbies these days? | D4: ='ALL(responses)'!D4 -> As an AI, I don't have personal experiences or hobbies in the way humans do. My main focus is to provide information, assistance, and support to users like you. Is there anything specific you would like help with or talk about today? | E4: ='ALL(responses)'!E4 -> 44635 | F4: =ROUND(('ALL(responses)'!F4 - MIN('ALL(responses)'!F$2:F$681)) / (MAX('ALL(responses)'!F$2:F$681)-MIN('ALL(responses)'!F$2:F$681)),3) -> 0 | G4: =ROUND(('ALL(responses)'!G4 - MIN('ALL(responses)'!G$2:G$681)) / (MAX('ALL(responses)'!G$2:G$681)-MIN('ALL(responses)'!G$2:G$681)),3) -> 0 | H4: =ROUND(('ALL(responses)'!H4 - MIN('ALL(responses)'!H$2:H$681)) / (MAX('ALL(responses)'!H$2:H$681)-MIN('ALL(responses)'!H$2:H$681)),3) -> 0.125 | I4: =ROUND(('ALL(responses)'!I4 - MIN('ALL(responses)'!I$2:I$681)) / (MAX('ALL(responses)'!I$2:I$681)-MIN('ALL(responses)'!I$2:I$681)),3) -> 0.25 | J4: =ROUND(('ALL(responses)'!J4 - MIN('ALL(responses)'!J$2:J$681)) / (MAX('ALL(responses)'!J$2:J$681)-MIN('ALL(responses)'!J$2:J$681)),3) -> 0 | K4: =ROUND(('ALL(responses)'!K4 - MIN('ALL(responses)'!K$2:K$681)) / (MAX('ALL(responses)'!K$2:K$681)-MIN('ALL(responses)'!K$2:K$681)),3) -> 0.599 | L4: =ROUND(('ALL(responses)'!L4 - MIN('ALL(responses)'!L$2:L$681)) / (MAX('ALL(responses)'!L$2:L$681)-MIN('ALL(responses)'!L$2:L$681)),3) -> 0.407 | M4: =ROUND(('ALL(responses)'!M4 - MIN('ALL(responses)'!M$2:M$681)) / (MAX('ALL(responses)'!M$2:M$681)-MIN('ALL(responses)'!M$2:M$681)),3) -> 0.44 | N4: =ROUND(('ALL(responses)'!P4 - MIN('ALL(responses)'!P$2:P$681)) / (MAX('ALL(responses)'!P$2:P$681)-MIN('ALL(responses)'!P$2:P$681)),3) -> 0.512 | O4: =ROUND(('ALL(responses)'!Q4 - MIN('ALL(responses)'!Q$2:Q$681)) / (MAX('ALL(responses)'!Q$2:Q$681)-MIN('ALL(responses)'!Q$2:Q$681)),3) -> 0.429 | P4: =ROUND(('ALL(responses)'!R4 - MIN('ALL(responses)'!R$2:R$681)) / (MAX('ALL(responses)'!R$2:R$681)-MIN('ALL(responses)'!R$2:R$681)),3) -> 0.856 | Q4: =ROUND(('ALL(responses)'!S4 - MIN('ALL(responses)'!S$2:S$681)) / (MAX('ALL(responses)'!S$2:S$681)-MIN('ALL(responses)'!S$2:S$681)),3) -> 0.928 | R4: =ROUND(('ALL(responses)'!T4 - MIN('ALL(responses)'!T$2:T$681)) / (MAX('ALL(responses)'!T$2:T$681)-MIN('ALL(responses)'!T$2:T$681)),3) -> 0.358 | S4: =average(F4:R4) -> 0.37723077
A5: ='ALL(responses)'!A5 -> A_NEUTRAL | B5: ='ALL(responses)'!B5 -> GPT-3.5 | C5: ='ALL(responses)'!C5 -> How’s work going for you these days? | D5: ='ALL(responses)'!D5 -> I'm here to assist you and provide information to the best of my abilities. How can I help you today? | E5: ='ALL(responses)'!E5 -> 44635 | F5: =ROUND(('ALL(responses)'!F5 - MIN('ALL(responses)'!F$2:F$681)) / (MAX('ALL(responses)'!F$2:F$681)-MIN('ALL(responses)'!F$2:F$681)),3) -> 0 | G5: =ROUND(('ALL(responses)'!G5 - MIN('ALL(responses)'!G$2:G$681)) / (MAX('ALL(responses)'!G$2:G$681)-MIN('ALL(responses)'!G$2:G$681)),3) -> 0 | H5: =ROUND(('ALL(responses)'!H5 - MIN('ALL(responses)'!H$2:H$681)) / (MAX('ALL(responses)'!H$2:H$681)-MIN('ALL(responses)'!H$2:H$681)),3) -> 0.5 | I5: =ROUND(('ALL(responses)'!I5 - MIN('ALL(responses)'!I$2:I$681)) / (MAX('ALL(responses)'!I$2:I$681)-MIN('ALL(responses)'!I$2:I$681)),3) -> 0.25 | J5: =ROUND(('ALL(responses)'!J5 - MIN('ALL(responses)'!J$2:J$681)) / (MAX('ALL(responses)'!J$2:J$681)-MIN('ALL(responses)'!J$2:J$681)),3) -> 0.375 | K5: =ROUND(('ALL(responses)'!K5 - MIN('ALL(responses)'!K$2:K$681)) / (MAX('ALL(responses)'!K$2:K$681)-MIN('ALL(responses)'!K$2:K$681)),3) -> 0.637 | L5: =ROUND(('ALL(responses)'!L5 - MIN('ALL(responses)'!L$2:L$681)) / (MAX('ALL(responses)'!L$2:L$681)-MIN('ALL(responses)'!L$2:L$681)),3) -> 0.523 | M5: =ROUND(('ALL(responses)'!M5 - MIN('ALL(responses)'!M$2:M$681)) / (MAX('ALL(responses)'!M$2:M$681)-MIN('ALL(responses)'!M$2:M$681)),3) -> 0.573 | N5: =ROUND(('ALL(responses)'!P5 - MIN('ALL(responses)'!P$2:P$681)) / (MAX('ALL(responses)'!P$2:P$681)-MIN('ALL(responses)'!P$2:P$681)),3) -> 0.524 | O5: =ROUND(('ALL(responses)'!Q5 - MIN('ALL(responses)'!Q$2:Q$681)) / (MAX('ALL(responses)'!Q$2:Q$681)-MIN('ALL(responses)'!Q$2:Q$681)),3) -> 0.9 | P5: =ROUND(('ALL(responses)'!R5 - MIN('ALL(responses)'!R$2:R$681)) / (MAX('ALL(responses)'!R$2:R$681)-MIN('ALL(responses)'!R$2:R$681)),3) -> 0.836 | Q5: =ROUND(('ALL(responses)'!S5 - MIN('ALL(responses)'!S$2:S$681)) / (MAX('ALL(responses)'!S$2:S$681)-MIN('ALL(responses)'!S$2:S$681)),3) -> 0.918 | R5: =ROUND(('ALL(responses)'!T5 - MIN('ALL(responses)'!T$2:T$681)) / (MAX('ALL(responses)'!T$2:T$681)-MIN('ALL(responses)'!T$2:T$681)),3) -> 0.295 | S5: =average(F5:R5) -> 0.487
A6: ='ALL(responses)'!A6 -> A_NEUTRAL | B6: ='ALL(responses)'!B6 -> GPT-3.5 | C6: ='ALL(responses)'!C6 -> Have you had any interesting projects come up recently? | D6: ='ALL(responses)'!D6 -> As an AI assistant, I don't have personal experiences or projects in the traditional sense. My main goal is to assist you with any questions or tasks you have. Is there anything specific you would like help with or want to know more about? | E6: ='ALL(responses)'!E6 -> 44635 | F6: =ROUND(('ALL(responses)'!F6 - MIN('ALL(responses)'!F$2:F$681)) / (MAX('ALL(responses)'!F$2:F$681)-MIN('ALL(responses)'!F$2:F$681)),3) -> 0 | G6: =ROUND(('ALL(responses)'!G6 - MIN('ALL(responses)'!G$2:G$681)) / (MAX('ALL(responses)'!G$2:G$681)-MIN('ALL(responses)'!G$2:G$681)),3) -> 0 | H6: =ROUND(('ALL(responses)'!H6 - MIN('ALL(responses)'!H$2:H$681)) / (MAX('ALL(responses)'!H$2:H$681)-MIN('ALL(responses)'!H$2:H$681)),3) -> 0.125 | I6: =ROUND(('ALL(responses)'!I6 - MIN('ALL(responses)'!I$2:I$681)) / (MAX('ALL(responses)'!I$2:I$681)-MIN('ALL(responses)'!I$2:I$681)),3) -> 0.25 | J6: =ROUND(('ALL(responses)'!J6 - MIN('ALL(responses)'!J$2:J$681)) / (MAX('ALL(responses)'!J$2:J$681)-MIN('ALL(responses)'!J$2:J$681)),3) -> 0 | K6: =ROUND(('ALL(responses)'!K6 - MIN('ALL(responses)'!K$2:K$681)) / (MAX('ALL(responses)'!K$2:K$681)-MIN('ALL(responses)'!K$2:K$681)),3) -> 0.582 | L6: =ROUND(('ALL(responses)'!L6 - MIN('ALL(responses)'!L$2:L$681)) / (MAX('ALL(responses)'!L$2:L$681)-MIN('ALL(responses)'!L$2:L$681)),3) -> 0.588 | M6: =ROUND(('ALL(responses)'!M6 - MIN('ALL(responses)'!M$2:M$681)) / (MAX('ALL(responses)'!M$2:M$681)-MIN('ALL(responses)'!M$2:M$681)),3) -> 0.483 | N6: =ROUND(('ALL(responses)'!P6 - MIN('ALL(responses)'!P$2:P$681)) / (MAX('ALL(responses)'!P$2:P$681)-MIN('ALL(responses)'!P$2:P$681)),3) -> 0.489 | O6: =ROUND(('ALL(responses)'!Q6 - MIN('ALL(responses)'!Q$2:Q$681)) / (MAX('ALL(responses)'!Q$2:Q$681)-MIN('ALL(responses)'!Q$2:Q$681)),3) -> 0.511 | P6: =ROUND(('ALL(responses)'!R6 - MIN('ALL(responses)'!R$2:R$681)) / (MAX('ALL(responses)'!R$2:R$681)-MIN('ALL(responses)'!R$2:R$681)),3) -> 0.671 | Q6: =ROUND(('ALL(responses)'!S6 - MIN('ALL(responses)'!S$2:S$681)) / (MAX('ALL(responses)'!S$2:S$681)-MIN('ALL(responses)'!S$2:S$681)),3) -> 0.835 | R6: =ROUND(('ALL(responses)'!T6 - MIN('ALL(responses)'!T$2:T$681)) / (MAX('ALL(responses)'!T$2:T$681)-MIN('ALL(responses)'!T$2:T$681)),3) -> 0.302 | S6: =average(F6:R6) -> 0.372
A7: ='ALL(responses)'!A7 -> A_NEUTRAL | B7: ='ALL(responses)'!B7 -> GPT-3.5 | C7: ='ALL(responses)'!C7 -> It’s been pretty cold lately, has that affected your routine? | D7: ='ALL(responses)'!D7 -> I don't have a physical form or experience the weather, so changes in temperature or weather conditions do not affect me. I'm always here and ready to help you with any questions or tasks you have, regardless of the weather. How can I assist you today? | E7: ='ALL(responses)'!E7 -> 44635 | F7: =ROUND(('ALL(responses)'!F7 - MIN('ALL(responses)'!F$2:F$681)) / (MAX('ALL(responses)'!F$2:F$681)-MIN('ALL(responses)'!F$2:F$681)),3) -> 0 | G7: =ROUND(('ALL(responses)'!G7 - MIN('ALL(responses)'!G$2:G$681)) / (MAX('ALL(responses)'!G$2:G$681)-MIN('ALL(responses)'!G$2:G$681)),3) -> 0 | H7: =ROUND(('ALL(responses)'!H7 - MIN('ALL(responses)'!H$2:H$681)) / (MAX('ALL(responses)'!H$2:H$681)-MIN('ALL(responses)'!H$2:H$681)),3) -> 0.125 | I7: =ROUND(('ALL(responses)'!I7 - MIN('ALL(responses)'!I$2:I$681)) / (MAX('ALL(responses)'!I$2:I$681)-MIN('ALL(responses)'!I$2:I$681)),3) -> 0.25 | J7: =ROUND(('ALL(responses)'!J7 - MIN('ALL(responses)'!J$2:J$681)) / (MAX('ALL(responses)'!J$2:J$681)-MIN('ALL(responses)'!J$2:J$681)),3) -> 0 | K7: =ROUND(('ALL(responses)'!K7 - MIN('ALL(responses)'!K$2:K$681)) / (MAX('ALL(responses)'!K$2:K$681)-MIN('ALL(responses)'!K$2:K$681)),3) -> 0.166 | L7: =ROUND(('ALL(responses)'!L7 - MIN('ALL(responses)'!L$2:L$681)) / (MAX('ALL(responses)'!L$2:L$681)-MIN('ALL(responses)'!L$2:L$681)),3) -> 0.045 | M7: =ROUND(('ALL(responses)'!M7 - MIN('ALL(responses)'!M$2:M$681)) / (MAX('ALL(responses)'!M$2:M$681)-MIN('ALL(responses)'!M$2:M$681)),3) -> 0.362 | N7: =ROUND(('ALL(responses)'!P7 - MIN('ALL(responses)'!P$2:P$681)) / (MAX('ALL(responses)'!P$2:P$681)-MIN('ALL(responses)'!P$2:P$681)),3) -> 0.229 | O7: =ROUND(('ALL(responses)'!Q7 - MIN('ALL(responses)'!Q$2:Q$681)) / (MAX('ALL(responses)'!Q$2:Q$681)-MIN('ALL(responses)'!Q$2:Q$681)),3) -> 0.587 | P7: =ROUND(('ALL(responses)'!R7 - MIN('ALL(responses)'!R$2:R$681)) / (MAX('ALL(responses)'!R$2:R$681)-MIN('ALL(responses)'!R$2:R$681)),3) -> 0.637 | Q7: =ROUND(('ALL(responses)'!S7 - MIN('ALL(responses)'!S$2:S$681)) / (MAX('ALL(responses)'!S$2:S$681)-MIN('ALL(responses)'!S$2:S$681)),3) -> 0.818 | R7: =ROUND(('ALL(responses)'!T7 - MIN('ALL(responses)'!T$2:T$681)) / (MAX('ALL(responses)'!T$2:T$681)-MIN('ALL(responses)'!T$2:T$681)),3) -> 0.459 | S7: =average(F7:R7) -> 0.28292308
A8: ='ALL(responses)'!A8 -> A_NEUTRAL | B8: ='ALL(responses)'!B8 -> GPT-3.5 | C8: ='ALL(responses)'!C8 -> Got any big plans for the weekend? | D8: ='ALL(responses)'!D8 -> As an AI, I don't have plans or weekends in the way humans do. My purpose is to assist you with any questions or tasks you have. Is there anything specific you would like help with or discuss today? | E8: ='ALL(responses)'!E8 -> 44635 | F8: =ROUND(('ALL(responses)'!F8 - MIN('ALL(responses)'!F$2:F$681)) / (MAX('ALL(responses)'!F$2:F$681)-MIN('ALL(responses)'!F$2:F$681)),3) -> 0 | G8: =ROUND(('ALL(responses)'!G8 - MIN('ALL(responses)'!G$2:G$681)) / (MAX('ALL(responses)'!G$2:G$681)-MIN('ALL(responses)'!G$2:G$681)),3) -> 0 | H8: =ROUND(('ALL(responses)'!H8 - MIN('ALL(responses)'!H$2:H$681)) / (MAX('ALL(responses)'!H$2:H$681)-MIN('ALL(responses)'!H$2:H$681)),3) -> 0.125 | I8: =ROUND(('ALL(responses)'!I8 - MIN('ALL(responses)'!I$2:I$681)) / (MAX('ALL(responses)'!I$2:I$681)-MIN('ALL(responses)'!I$2:I$681)),3) -> 0.25 | J8: =ROUND(('ALL(responses)'!J8 - MIN('ALL(responses)'!J$2:J$681)) / (MAX('ALL(responses)'!J$2:J$681)-MIN('ALL(responses)'!J$2:J$681)),3) -> 0 | K8: =ROUND(('ALL(responses)'!K8 - MIN('ALL(responses)'!K$2:K$681)) / (MAX('ALL(responses)'!K$2:K$681)-MIN('ALL(responses)'!K$2:K$681)),3) -> 0.624 | L8: =ROUND(('ALL(responses)'!L8 - MIN('ALL(responses)'!L$2:L$681)) / (MAX('ALL(responses)'!L$2:L$681)-MIN('ALL(responses)'!L$2:L$681)),3) -> 0.414 | M8: =ROUND(('ALL(responses)'!M8 - MIN('ALL(responses)'!M$2:M$681)) / (MAX('ALL(responses)'!M$2:M$681)-MIN('ALL(responses)'!M$2:M$681)),3) -> 0.429 | N8: =ROUND(('ALL(responses)'!P8 - MIN('ALL(responses)'!P$2:P$681)) / (MAX('ALL(responses)'!P$2:P$681)-MIN('ALL(responses)'!P$2:P$681)),3) -> 0.275 | O8: =ROUND(('ALL(responses)'!Q8 - MIN('ALL(responses)'!Q$2:Q$681)) / (MAX('ALL(responses)'!Q$2:Q$681)-MIN('ALL(responses)'!Q$2:Q$681)),3) -> 0.577 | P8: =ROUND(('ALL(responses)'!R8 - MIN('ALL(responses)'!R$2:R$681)) / (MAX('ALL(responses)'!R$2:R$681)-MIN('ALL(responses)'!R$2:R$681)),3) -> 0.637 | Q8: =ROUND(('ALL(responses)'!S8 - MIN('ALL(responses)'!S$2:S$681)) / (MAX('ALL(responses)'!S$2:S$681)-MIN('ALL(responses)'!S$2:S$681)),3) -> 0.818 | R8: =ROUND(('ALL(responses)'!T8 - MIN('ALL(responses)'!T$2:T$681)) / (MAX('ALL(responses)'!T$2:T$681)-MIN('ALL(responses)'!T$2:T$681)),3) -> 0.229 | S8: =average(F8:R8) -> 0.33676923
A9: ='ALL(responses)'!A9 -> A_NEUTRAL | B9: ='ALL(responses)'!B9 -> GPT-3.5 | C9: ='ALL(responses)'!C9 -> What’s something new you’ve tried recently? | D9: ='ALL(responses)'!D9 -> As an AI, I don't try new things or have personal experiences in the way humans do. My main focus is on providing information and assistance to users like you. Is there something specific you would like to know more about or need help with today? | E9: ='ALL(responses)'!E9 -> 44635 | F9: =ROUND(('ALL(responses)'!F9 - MIN('ALL(responses)'!F$2:F$681)) / (MAX('ALL(responses)'!F$2:F$681)-MIN('ALL(responses)'!F$2:F$681)),3) -> 0 | G9: =ROUND(('ALL(responses)'!G9 - MIN('ALL(responses)'!G$2:G$681)) / (MAX('ALL(responses)'!G$2:G$681)-MIN('ALL(responses)'!G$2:G$681)),3) -> 0 | H9: =ROUND(('ALL(responses)'!H9 - MIN('ALL(responses)'!H$2:H$681)) / (MAX('ALL(responses)'!H$2:H$681)-MIN('ALL(responses)'!H$2:H$681)),3) -> 0.125 | I9: =ROUND(('ALL(responses)'!I9 - MIN('ALL(responses)'!I$2:I$681)) / (MAX('ALL(responses)'!I$2:I$681)-MIN('ALL(responses)'!I$2:I$681)),3) -> 0.25 | J9: =ROUND(('ALL(responses)'!J9 - MIN('ALL(responses)'!J$2:J$681)) / (MAX('ALL(responses)'!J$2:J$681)-MIN('ALL(responses)'!J$2:J$681)),3) -> 0 | K9: =ROUND(('ALL(responses)'!K9 - MIN('ALL(responses)'!K$2:K$681)) / (MAX('ALL(responses)'!K$2:K$681)-MIN('ALL(responses)'!K$2:K$681)),3) -> 0.57 | L9: =ROUND(('ALL(responses)'!L9 - MIN('ALL(responses)'!L$2:L$681)) / (MAX('ALL(responses)'!L$2:L$681)-MIN('ALL(responses)'!L$2:L$681)),3) -> 0.482 | M9: =ROUND(('ALL(responses)'!M9 - MIN('ALL(responses)'!M$2:M$681)) / (MAX('ALL(responses)'!M$2:M$681)-MIN('ALL(responses)'!M$2:M$681)),3) -> 0.453 | N9: =ROUND(('ALL(responses)'!P9 - MIN('ALL(responses)'!P$2:P$681)) / (MAX('ALL(responses)'!P$2:P$681)-MIN('ALL(responses)'!P$2:P$681)),3) -> 0.468 | O9: =ROUND(('ALL(responses)'!Q9 - MIN('ALL(responses)'!Q$2:Q$681)) / (MAX('ALL(responses)'!Q$2:Q$681)-MIN('ALL(responses)'!Q$2:Q$681)),3) -> 0.391 | P9: =ROUND(('ALL(responses)'!R9 - MIN('ALL(responses)'!R$2:R$681)) / (MAX('ALL(responses)'!R$2:R$681)-MIN('ALL(responses)'!R$2:R$681)),3) -> 0.772 | Q9: =ROUND(('ALL(responses)'!S9 - MIN('ALL(responses)'!S$2:S$681)) / (MAX('ALL(responses)'!S$2:S$681)-MIN('ALL(responses)'!S$2:S$681)),3) -> 0.886 | R9: =ROUND(('ALL(responses)'!T9 - MIN('ALL(responses)'!T$2:T$681)) / (MAX('ALL(responses)'!T$2:T$681)-MIN('ALL(responses)'!T$2:T$681)),3) -> 0.295 | S9: =average(F9:R9) -> 0.36092308
A10: ='ALL(responses)'!A10 -> A_NEUTRAL | B10: ='ALL(responses)'!B10 -> GPT-3.5 | C10: ='ALL(responses)'!C10 -> Do you work on a team or more independently? | D10: ='ALL(responses)'!D10 -> I operate as an independent AI assistant, designed to provide information and support to users like you. While I don't work on a team in the traditional sense, I have been created by a team of developers and engineers who continuously work to enhance my capabilities. How can I assist you today? | E10: ='ALL(responses)'!E10 -> 44635 | F10: =ROUND(('ALL(responses)'!F10 - MIN('ALL(responses)'!F$2:F$681)) / (MAX('ALL(responses)'!F$2:F$681)-MIN('ALL(responses)'!F$2:F$681)),3) -> 0 | G10: =ROUND(('ALL(responses)'!G10 - MIN('ALL(responses)'!G$2:G$681)) / (MAX('ALL(responses)'!G$2:G$681)-MIN('ALL(responses)'!G$2:G$681)),3) -> 0 | H10: =ROUND(('ALL(responses)'!H10 - MIN('ALL(responses)'!H$2:H$681)) / (MAX('ALL(responses)'!H$2:H$681)-MIN('ALL(responses)'!H$2:H$681)),3) -> 0.125 | I10: =ROUND(('ALL(responses)'!I10 - MIN('ALL(responses)'!I$2:I$681)) / (MAX('ALL(responses)'!I$2:I$681)-MIN('ALL(responses)'!I$2:I$681)),3) -> 0.25 | J10: =ROUND(('ALL(responses)'!J10 - MIN('ALL(responses)'!J$2:J$681)) / (MAX('ALL(responses)'!J$2:J$681)-MIN('ALL(responses)'!J$2:J$681)),3) -> 0 | K10: =ROUND(('ALL(responses)'!K10 - MIN('ALL(responses)'!K$2:K$681)) / (MAX('ALL(responses)'!K$2:K$681)-MIN('ALL(responses)'!K$2:K$681)),3) -> 0.479 | L10: =ROUND(('ALL(responses)'!L10 - MIN('ALL(responses)'!L$2:L$681)) / (MAX('ALL(responses)'!L$2:L$681)-MIN('ALL(responses)'!L$2:L$681)),3) -> 0.415 | M10: =ROUND(('ALL(responses)'!M10 - MIN('ALL(responses)'!M$2:M$681)) / (MAX('ALL(responses)'!M$2:M$681)-MIN('ALL(responses)'!M$2:M$681)),3) -> 0.207 | N10: =ROUND(('ALL(responses)'!P10 - MIN('ALL(responses)'!P$2:P$681)) / (MAX('ALL(responses)'!P$2:P$681)-MIN('ALL(responses)'!P$2:P$681)),3) -> 0.208 | O10: =ROUND(('ALL(responses)'!Q10 - MIN('ALL(responses)'!Q$2:Q$681)) / (MAX('ALL(responses)'!Q$2:Q$681)-MIN('ALL(responses)'!Q$2:Q$681)),3) -> 0.606 | P10: =ROUND(('ALL(responses)'!R10 - MIN('ALL(responses)'!R$2:R$681)) / (MAX('ALL(responses)'!R$2:R$681)-MIN('ALL(responses)'!R$2:R$681)),3) -> 0.735 | Q10: =ROUND(('ALL(responses)'!S10 - MIN('ALL(responses)'!S$2:S$681)) / (MAX('ALL(responses)'!S$2:S$681)-MIN('ALL(responses)'!S$2:S$681)),3) -> 0.867 | R10: =ROUND(('ALL(responses)'!T10 - MIN('ALL(responses)'!T$2:T$681)) / (MAX('ALL(responses)'!T$2:T$681)-MIN('ALL(responses)'!T$2:T$681)),3) -> 0.471 | S10: =average(F10:R10) -> 0.33561538
A11: ='ALL(responses)'!A11 -> A_NEUTRAL | B11: ='ALL(responses)'!B11 -> GPT-3.5 | C11: ='ALL(responses)'!C11 -> How do you handle stress at work when things get busy? | D11: ='ALL(responses)'!D11 -> As an AI, I don't experience stress in the same way humans do, so I don't get overwhelmed or need to manage stress. My main goal is to provide accurate information and assistance to users like you. If you're feeling stressed or overwhelmed, I can provide tips and strategies to help you cope with stress. Let me know how I can support you. | E11: ='ALL(responses)'!E11 -> 44635 | F11: =ROUND(('ALL(responses)'!F11 - MIN('ALL(responses)'!F$2:F$681)) / (MAX('ALL(responses)'!F$2:F$681)-MIN('ALL(responses)'!F$2:F$681)),3) -> 0 | G11: =ROUND(('ALL(responses)'!G11 - MIN('ALL(responses)'!G$2:G$681)) / (MAX('ALL(responses)'!G$2:G$681)-MIN('ALL(responses)'!G$2:G$681)),3) -> 0 | H11: =ROUND(('ALL(responses)'!H11 - MIN('ALL(responses)'!H$2:H$681)) / (MAX('ALL(responses)'!H$2:H$681)-MIN('ALL(responses)'!H$2:H$681)),3) -> 0.125 | I11: =ROUND(('ALL(responses)'!I11 - MIN('ALL(responses)'!I$2:I$681)) / (MAX('ALL(responses)'!I$2:I$681)-MIN('ALL(responses)'!I$2:I$681)),3) -> 0 | J11: =ROUND(('ALL(responses)'!J11 - MIN('ALL(responses)'!J$2:J$681)) / (MAX('ALL(responses)'!J$2:J$681)-MIN('ALL(responses)'!J$2:J$681)),3) -> 0 | K11: =ROUND(('ALL(responses)'!K11 - MIN('ALL(responses)'!K$2:K$681)) / (MAX('ALL(responses)'!K$2:K$681)-MIN('ALL(responses)'!K$2:K$681)),3) -> 0.453 | L11: =ROUND(('ALL(responses)'!L11 - MIN('ALL(responses)'!L$2:L$681)) / (MAX('ALL(responses)'!L$2:L$681)-MIN('ALL(responses)'!L$2:L$681)),3) -> 0.389 | M11: =ROUND(('ALL(responses)'!M11 - MIN('ALL(responses)'!M$2:M$681)) / (MAX('ALL(responses)'!M$2:M$681)-MIN('ALL(responses)'!M$2:M$681)),3) -> 0.338 | N11: =ROUND(('ALL(responses)'!P11 - MIN('ALL(responses)'!P$2:P$681)) / (MAX('ALL(responses)'!P$2:P$681)-MIN('ALL(responses)'!P$2:P$681)),3) -> 0.333 | O11: =ROUND(('ALL(responses)'!Q11 - MIN('ALL(responses)'!Q$2:Q$681)) / (MAX('ALL(responses)'!Q$2:Q$681)-MIN('ALL(responses)'!Q$2:Q$681)),3) -> 0.714 | P11: =ROUND(('ALL(responses)'!R11 - MIN('ALL(responses)'!R$2:R$681)) / (MAX('ALL(responses)'!R$2:R$681)-MIN('ALL(responses)'!R$2:R$681)),3) -> 0.418 | Q11: =ROUND(('ALL(responses)'!S11 - MIN('ALL(responses)'!S$2:S$681)) / (MAX('ALL(responses)'!S$2:S$681)-MIN('ALL(responses)'!S$2:S$681)),3) -> 0.709 | R11: =ROUND(('ALL(responses)'!T11 - MIN('ALL(responses)'!T$2:T$681)) / (MAX('ALL(responses)'!T$2:T$681)-MIN('ALL(responses)'!T$2:T$681)),3) -> 0.298 | S11: =average(F11:R11) -> 0.29053846
A12: ='ALL(responses)'!A12 -> B_MILDLYINTIMATE | B12: ='ALL(responses)'!B12 -> GPT-3.5 | C12: ='ALL(responses)'!C12 -> What's your favorite food to eat on a relaxing night in? | D12: ='ALL(responses)'!D12 -> As an AI, I don't have personal preferences or the ability to eat. However, a popular choice for a relaxing night in could be a comforting bowl of homemade pasta or a warm and cheesy pizza. What's your favorite food to enjoy on a relaxing night in? | E12: ='ALL(responses)'!E12 -> 44635 | F12: =ROUND(('ALL(responses)'!F12 - MIN('ALL(responses)'!F$2:F$681)) / (MAX('ALL(responses)'!F$2:F$681)-MIN('ALL(responses)'!F$2:F$681)),3) -> 0 | G12: =ROUND(('ALL(responses)'!G12 - MIN('ALL(responses)'!G$2:G$681)) / (MAX('ALL(responses)'!G$2:G$681)-MIN('ALL(responses)'!G$2:G$681)),3) -> 0 | H12: =ROUND(('ALL(responses)'!H12 - MIN('ALL(responses)'!H$2:H$681)) / (MAX('ALL(responses)'!H$2:H$681)-MIN('ALL(responses)'!H$2:H$681)),3) -> 0.125 | I12: =ROUND(('ALL(responses)'!I12 - MIN('ALL(responses)'!I$2:I$681)) / (MAX('ALL(responses)'!I$2:I$681)-MIN('ALL(responses)'!I$2:I$681)),3) -> 0 | J12: =ROUND(('ALL(responses)'!J12 - MIN('ALL(responses)'!J$2:J$681)) / (MAX('ALL(responses)'!J$2:J$681)-MIN('ALL(responses)'!J$2:J$681)),3) -> 0 | K12: =ROUND(('ALL(responses)'!K12 - MIN('ALL(responses)'!K$2:K$681)) / (MAX('ALL(responses)'!K$2:K$681)-MIN('ALL(responses)'!K$2:K$681)),3) -> 0.365 | L12: =ROUND(('ALL(responses)'!L12 - MIN('ALL(responses)'!L$2:L$681)) / (MAX('ALL(responses)'!L$2:L$681)-MIN('ALL(responses)'!L$2:L$681)),3) -> 0.398 | M12: =ROUND(('ALL(responses)'!M12 - MIN('ALL(responses)'!M$2:M$681)) / (MAX('ALL(responses)'!M$2:M$681)-MIN('ALL(responses)'!M$2:M$681)),3) -> 0.482 | N12: =ROUND(('ALL(responses)'!P12 - MIN('ALL(responses)'!P$2:P$681)) / (MAX('ALL(responses)'!P$2:P$681)-MIN('ALL(responses)'!P$2:P$681)),3) -> 0.224 | O12: =ROUND(('ALL(responses)'!Q12 - MIN('ALL(responses)'!Q$2:Q$681)) / (MAX('ALL(responses)'!Q$2:Q$681)-MIN('ALL(responses)'!Q$2:Q$681)),3) -> 0.191 | P12: =ROUND(('ALL(responses)'!R12 - MIN('ALL(responses)'!R$2:R$681)) / (MAX('ALL(responses)'!R$2:R$681)-MIN('ALL(responses)'!R$2:R$681)),3) -> 0.965 | Q12: =ROUND(('ALL(responses)'!S12 - MIN('ALL(responses)'!S$2:S$681)) / (MAX('ALL(responses)'!S$2:S$681)-MIN('ALL(responses)'!S$2:S$681)),3) -> 0.983 | R12: =ROUND(('ALL(responses)'!T12 - MIN('ALL(responses)'!T$2:T$681)) / (MAX('ALL(responses)'!T$2:T$681)-MIN('ALL(responses)'!T$2:T$681)),3) -> 0.412 | S12: =average(F12:R12) -> 0.31884615
